<mujoco model='XtellarRobotics/ToGo_LFs_v0p1_prototype'>
    <compiler meshdir='../meshes' />

    <default>
        <default class="vis">
            <geom
                type="mesh" rgba="0.7529411764705882 0.7529411764705882 0.7529411764705882 1.0"
                group="1"
                contype="0" conaffinity="0" density="0"
            />
        </default>
        <default class="vis_rubber">
            <geom
                type="mesh" rgba="0.149 0.149 0.149 1.0"
                group="1"
                contype="0" conaffinity="0" density="0"
            />
        </default>
        <default class="col">
            <geom
                type="mesh" rgba="0.7529411764705882 0.7529411764705882 0.7529411764705882 1.0"
                group="3"
                contype="1" conaffinity="1" density="0"
                solref="0.005 1" solimp="0.95 0.99 0.001 0.5 2"
            />
        </default>
        <default class="col_rubber">
            <geom
                type="mesh" rgba="0.149 0.149 0.149 1.0"
                group="3"
                contype="1" conaffinity="1" density="0"
                solref="0.005 1" solimp="0.95 0.99 0.001 0.5 2"
                condim="6" friction="1.5 0.02 0.001"
            />
        </default>
    </default>

    <asset>
        <mesh name='vis_m0_torso'   file='visual/m0_torso.stl'      scale='0.001 0.001 0.001' />
        <!-- front left leg -->
        <mesh name='vis_mfl1_hipr'  file='visual/mfl1_hipr.stl'     scale='0.001 0.001 0.001' />
        <mesh name='vis_mfl2_hipp'  file='visual/mfl2_hipp.stl'     scale='0.001 0.001 0.001' />
        <mesh name='vis_mfl3_knee'  file='visual/mfl3_knee.stl'     scale='0.001 0.001 0.001' />
        <mesh name='vis_mfl4_foot'  file='visual/mfl4_foot.stl'     scale='0.001 0.001 0.001' />
        <!-- front right leg -->
        <mesh name='vis_mfr1_hipr'  file='visual/mfr1_hipr.stl'     scale='0.001 0.001 0.001' />
        <mesh name='vis_mfr2_hipp'  file='visual/mfr2_hipp.stl'     scale='0.001 0.001 0.001' />
        <mesh name='vis_mfr3_knee'  file='visual/mfr3_knee.stl'     scale='0.001 0.001 0.001' />
        <mesh name='vis_mfr4_foot'  file='visual/mfr4_foot.stl'     scale='0.001 0.001 0.001' />
        <!-- rear left leg -->
        <mesh name='vis_mrl1_hipr'  file='visual/mrl1_hipr.stl'     scale='0.001 0.001 0.001' />
        <mesh name='vis_mrl2_hipp'  file='visual/mrl2_hipp.stl'     scale='0.001 0.001 0.001' />
        <mesh name='vis_mrl3_knee'  file='visual/mrl3_knee.stl'     scale='0.001 0.001 0.001' />
        <mesh name='vis_mrl4_foot'  file='visual/mrl4_foot.stl'     scale='0.001 0.001 0.001' />
        <!-- rear right leg -->
        <mesh name='vis_mrr1_hipr'  file='visual/mrr1_hipr.stl'     scale='0.001 0.001 0.001' />
        <mesh name='vis_mrr2_hipp'  file='visual/mrr2_hipp.stl'     scale='0.001 0.001 0.001' />
        <mesh name='vis_mrr3_knee'  file='visual/mrr3_knee.stl'     scale='0.001 0.001 0.001' />
        <mesh name='vis_mrr4_foot'  file='visual/mrr4_foot.stl'     scale='0.001 0.001 0.001' />

        <mesh name='col_m0_torso'   file='collision/m0_torso.stl'   scale='0.001 0.001 0.001' />
        <!-- front left leg -->
        <mesh name='col_mfl1_hipr'  file='collision/mfl1_hipr.stl'  scale='0.001 0.001 0.001' />
        <mesh name='col_mfl2_hipp'  file='collision/mfl2_hipp.stl'  scale='0.001 0.001 0.001' />
        <mesh name='col_mfl3_knee'  file='collision/mfl3_knee.stl'  scale='0.001 0.001 0.001' />
        <mesh name='col_mfl4_foot'  file='collision/mfl4_foot.stl'  scale='0.001 0.001 0.001' />
        <!-- front right leg -->
        <mesh name='col_mfr1_hipr'  file='collision/mfr1_hipr.stl'  scale='0.001 0.001 0.001' />
        <mesh name='col_mfr2_hipp'  file='collision/mfr2_hipp.stl'  scale='0.001 0.001 0.001' />
        <mesh name='col_mfr3_knee'  file='collision/mfr3_knee.stl'  scale='0.001 0.001 0.001' />
        <mesh name='col_mfr4_foot'  file='collision/mfr4_foot.stl'  scale='0.001 0.001 0.001' />
        <!-- rear left leg -->
        <mesh name='col_mrl1_hipr'  file='collision/mrl1_hipr.stl'  scale='0.001 0.001 0.001' />
        <mesh name='col_mrl2_hipp'  file='collision/mrl2_hipp.stl'  scale='0.001 0.001 0.001' />
        <mesh name='col_mrl3_knee'  file='collision/mrl3_knee.stl'  scale='0.001 0.001 0.001' />
        <mesh name='col_mrl4_foot'  file='collision/mrl4_foot.stl'  scale='0.001 0.001 0.001' />
        <!-- rear right leg -->
        <mesh name='col_mrr1_hipr'  file='collision/mrr1_hipr.stl'  scale='0.001 0.001 0.001' />
        <mesh name='col_mrr2_hipp'  file='collision/mrr2_hipp.stl'  scale='0.001 0.001 0.001' />
        <mesh name='col_mrr3_knee'  file='collision/mrr3_knee.stl'  scale='0.001 0.001 0.001' />
        <mesh name='col_mrr4_foot'  file='collision/mrr4_foot.stl'  scale='0.001 0.001 0.001' />
    </asset>

    <worldbody>
        <body
            name="F_base"
            pos="0.000000000e+00 0.000000000e+00 0.000000000e+00"
            euler="0.000000000e+00 0.000000000e+00 0.000000000e+00"
        >
            <body
                name="L0_torso"
                pos="0.000000000e+00 0.000000000e+00 0.000000000e+00"
                euler="-0.000000000e+00 0.000000000e+00 -0.000000000e+00"
            >
                <inertial
                    pos="4.462000000e-04 3.737000000e-03 5.159860000e-02"
                    mass="7.753978700e+00"
                    fullinertia="4.092640000e-02 9.001370000e-02 1.095425000e-01 -5.256000000e-04 -1.022600000e-03 2.725000000e-04"
                />
                <geom class="vis" mesh="vis_m0_torso" />
                <geom class="col" mesh="col_m0_torso" />

                <site name="imu" pos="8.315000000e-02 0.000000000e+00 7.700000000e-02" euler="-0.000000000e+00 0.000000000e+00 -0.000000000e+00" />

                <!-- front left leg -->
                <body
                    name="Lfl1_hipr"
                    pos="1.260000000e-01 6.250000000e-02 4.500000000e-02"
                    euler="-0.000000000e+00 0.000000000e+00 -0.000000000e+00"
                >
                    <joint
                        name="Jfl1_hipr"
                        type="hinge"
                        axis="1.0 0.0 0.0"
                        range="-2.500000000e+01 2.500000000e+01"
                        armature="0.006180843"
                        damping="0.007"
                        frictionloss="0.194"
                    />
                    <inertial
                        pos="2.417210000e-02 -1.808690000e-02 1.600000000e-06"
                        mass="1.078132000e-01"
                        fullinertia="8.220000000e-05 9.000000000e-05 8.940000000e-05 6.700000000e-06 0.000000000e+00 0.000000000e+00"
                    />
                    <geom class="vis" mesh="vis_mfl1_hipr" />
                    <geom class="col" mesh="col_mfl1_hipr" />

                    <body
                        name="Lfl2_hipp"
                        pos="4.650000000e-02 -3.990000000e-02 0.000000000e+00"
                        euler="-0.000000000e+00 0.000000000e+00 -0.000000000e+00"
                    >
                        <joint
                            name="Jfl2_hipp"
                            type="hinge"
                            axis="0.0 1.0 0.0"
                            range="-1.100000000e+02 1.100000000e+02"
                            armature="0.006180843"
                            damping="0.007"
                            frictionloss="0.194"
                        />
                        <inertial
                            pos="-2.005190000e-02 8.413670000e-02 2.528300000e-03"
                            mass="1.510354600e+00"
                            fullinertia="3.929300000e-03 4.882300000e-03 7.857800000e-03 1.879900000e-03 3.603000000e-04 -2.467000000e-04"
                        />
                        <geom class="vis" mesh="vis_mfl2_hipp" />
                        <geom class="col" mesh="col_mfl2_hipp" />

                        <body
                            name="Lfl3_knee"
                            pos="-2.000000000e-01 1.458000000e-01 0.000000000e+00"
                            euler="-0.000000000e+00 0.000000000e+00 -0.000000000e+00"
                        >
                            <joint
                                name="Jfl3_knee"
                                type="hinge"
                                axis="0.0 1.0 0.0"
                                range="0.000000000e+00 1.000000000e+02"
                                armature="0.006180843"
                                damping="0.007"
                                frictionloss="0.194"
                            />
                            <inertial
                                pos="1.119741000e-01 0.000000000e+00 -3.990870000e-02"
                                mass="3.694785000e-01"
                                fullinertia="5.015000000e-04 2.553300000e-03 2.082600000e-03 0.000000000e+00 8.986000000e-04 0.000000000e+00"
                            />
                            <geom class="vis" mesh="vis_mfl3_knee" />
                            <geom class="col" mesh="col_mfl3_knee" />

                            <body
                                name="Lfl4_foot"
                                pos="1.942564000e-01 0.000000000e+00 -8.890640000e-02"
                                euler="0.000000000e+00 -3.799999910e+01 0.000000000e+00"
                            >
                                <inertial
                                    pos="5.000000000e-07 -8.500000000e-06 -8.971600000e-03"
                                    mass="8.600240000e-02"
                                    fullinertia="2.820000000e-05 2.870000000e-05 3.350000000e-05 0.000000000e+00 0.000000000e+00 0.000000000e+00"
                                />
                                <geom class="vis_rubber" mesh="vis_mfl4_foot" />
                                <geom class="col_rubber" mesh="col_mfl4_foot" />
                            </body>
                        </body>
                    </body>
                </body>

                <!-- front right leg -->
                <body
                    name="Lfr1_hipr"
                    pos="1.260000000e-01 -6.250000000e-02 4.500000000e-02"
                    euler="-0.000000000e+00 0.000000000e+00 -0.000000000e+00"
                >
                    <joint
                        name="Jfr1_hipr"
                        type="hinge"
                        axis="1.0 0.0 0.0"
                        range="-2.500000000e+01 2.500000000e+01"
                        armature="0.006180843"
                        damping="0.007"
                        frictionloss="0.194"
                    />
                    <inertial
                        pos="2.417210000e-02 1.808690000e-02 -1.600000000e-06"
                        mass="1.078132000e-01"
                        fullinertia="8.220000000e-05 9.000000000e-05 8.940000000e-05 -6.700000000e-06 0.000000000e+00 0.000000000e+00"
                    />
                    <geom class="vis" mesh="vis_mfr1_hipr" />
                    <geom class="col" mesh="col_mfr1_hipr" />

                    <body
                        name="Lfr2_hipp"
                        pos="4.650000000e-02 3.990000000e-02 0.000000000e+00"
                        euler="-0.000000000e+00 0.000000000e+00 -0.000000000e+00"
                    >
                        <joint
                            name="Jfr2_hipp"
                            type="hinge"
                            axis="0.0 -1.0 0.0"
                            range="-1.100000000e+02 1.100000000e+02"
                            armature="0.006180843"
                            damping="0.007"
                            frictionloss="0.194"
                        />
                        <inertial
                            pos="-2.005200000e-02 -8.413660000e-02 2.646100000e-03"
                            mass="1.510350900e+00"
                            fullinertia="3.928400000e-03 4.881300000e-03 7.857700000e-03 -1.879900000e-03 3.634000000e-04 2.345000000e-04"
                        />
                        <geom class="vis" mesh="vis_mfr2_hipp" />
                        <geom class="col" mesh="col_mfr2_hipp" />

                        <body
                            name="Lfr3_knee"
                            pos="-2.000000000e-01 -1.458000000e-01 0.000000000e+00"
                            euler="-0.000000000e+00 0.000000000e+00 -0.000000000e+00"
                        >
                            <joint
                                name="Jfr3_knee"
                                type="hinge"
                                axis="0.0 -1.0 0.0"
                                range="-1.000000000e+02 0.000000000e+00"
                                armature="0.006180843"
                                damping="0.007"
                                frictionloss="0.194"
                            />
                            <inertial
                                pos="1.119741000e-01 0.000000000e+00 -3.990870000e-02"
                                mass="3.694785000e-01"
                                fullinertia="5.015000000e-04 2.553300000e-03 2.082600000e-03 0.000000000e+00 8.986000000e-04 0.000000000e+00"
                            />
                            <geom class="vis" mesh="vis_mfr3_knee" />
                            <geom class="col" mesh="col_mfr3_knee" />

                            <body
                                name="Lfr4_foot"
                                pos="1.942564000e-01 0.000000000e+00 -8.890640000e-02"
                                euler="0.000000000e+00 -3.799999910e+01 0.000000000e+00"
                            >
                                <inertial
                                    pos="5.000000000e-07 -8.500000000e-06 -8.971600000e-03"
                                    mass="8.600240000e-02"
                                    fullinertia="2.820000000e-05 2.870000000e-05 3.350000000e-05 0.000000000e+00 0.000000000e+00 0.000000000e+00"
                                />
                                <geom class="vis_rubber" mesh="vis_mfr4_foot" />
                                <geom class="col_rubber" mesh="col_mfr4_foot" />
                            </body>
                        </body>
                    </body>
                </body>

                <!-- rear left leg -->
                <body
                    name="Lrl1_hipr"
                    pos="-1.268000000e-01 6.250000000e-02 4.500000000e-02"
                    euler="-0.000000000e+00 0.000000000e+00 -0.000000000e+00"
                >
                    <joint
                        name="Jrl1_hipr"
                        type="hinge"
                        axis="-1.0 0.0 0.0"
                        range="-2.500000000e+01 2.500000000e+01"
                        armature="0.006180843"
                        damping="0.007"
                        frictionloss="0.194"
                    />
                    <inertial
                        pos="-2.417210000e-02 -1.808690000e-02 -1.600000000e-06"
                        mass="1.078132000e-01"
                        fullinertia="8.220000000e-05 9.000000000e-05 8.940000000e-05 -6.700000000e-06 0.000000000e+00 0.000000000e+00"
                    />
                    <geom class="vis" mesh="vis_mrl1_hipr" />
                    <geom class="col" mesh="col_mrl1_hipr" />

                    <body
                        name="Lrl2_hipp"
                        pos="-4.650000000e-02 -3.990000000e-02 0.000000000e+00"
                        euler="-0.000000000e+00 0.000000000e+00 -0.000000000e+00"
                    >
                        <joint
                            name="Jrl2_hipp"
                            type="hinge"
                            axis="0.0 1.0 0.0"
                            range="-1.100000000e+02 1.100000000e+02"
                            armature="0.006180843"
                            damping="0.007"
                            frictionloss="0.194"
                        />
                        <inertial
                            pos="-2.005190000e-02 8.413670000e-02 2.528300000e-03"
                            mass="1.510354600e+00"
                            fullinertia="3.929300000e-03 4.882300000e-03 7.857800000e-03 1.879900000e-03 3.603000000e-04 -2.467000000e-04"
                        />
                        <geom class="vis" mesh="vis_mrl2_hipp" />
                        <geom class="col" mesh="col_mrl2_hipp" />

                        <body
                            name="Lrl3_knee"
                            pos="-2.000000000e-01 1.458000000e-01 0.000000000e+00"
                            euler="-0.000000000e+00 0.000000000e+00 -0.000000000e+00"
                        >
                            <joint
                                name="Jrl3_knee"
                                type="hinge"
                                axis="0.0 1.0 0.0"
                                range="0.000000000e+00 1.000000000e+02"
                                armature="0.006180843"
                                damping="0.007"
                                frictionloss="0.194"
                            />
                            <inertial
                                pos="1.119741000e-01 0.000000000e+00 -3.990870000e-02"
                                mass="3.694785000e-01"
                                fullinertia="5.015000000e-04 2.553300000e-03 2.082600000e-03 0.000000000e+00 8.986000000e-04 0.000000000e+00"
                            />
                            <geom class="vis" mesh="vis_mrl3_knee" />
                            <geom class="col" mesh="col_mrl3_knee" />

                            <body
                                name="Lrl4_foot"
                                pos="1.942564000e-01 0.000000000e+00 -8.890640000e-02"
                                euler="0.000000000e+00 -3.799999910e+01 0.000000000e+00"
                            >
                                <inertial
                                    pos="5.000000000e-07 -8.500000000e-06 -8.971600000e-03"
                                    mass="8.600240000e-02"
                                    fullinertia="2.820000000e-05 2.870000000e-05 3.350000000e-05 0.000000000e+00 0.000000000e+00 0.000000000e+00"
                                />
                                <geom class="vis_rubber" mesh="vis_mrl4_foot" />
                                <geom class="col_rubber" mesh="col_mrl4_foot" />
                            </body>
                        </body>
                    </body>
                </body>

                <!-- rear right leg -->
                <body
                    name="Lrr1_hipr"
                    pos="-1.268000000e-01 -6.250000000e-02 4.500000000e-02"
                    euler="-0.000000000e+00 0.000000000e+00 -0.000000000e+00"
                >
                    <joint
                        name="Jrr1_hipr"
                        type="hinge"
                        axis="-1.0 0.0 0.0"
                        range="-2.500000000e+01 2.500000000e+01"
                        armature="0.006180843"
                        damping="0.007"
                        frictionloss="0.194"
                    />
                    <inertial
                        pos="-2.417210000e-02 1.808690000e-02 1.600000000e-06"
                        mass="1.078132000e-01"
                        fullinertia="8.220000000e-05 9.000000000e-05 8.940000000e-05 6.700000000e-06 0.000000000e+00 0.000000000e+00"
                    />
                    <geom class="vis" mesh="vis_mrr1_hipr" />
                    <geom class="col" mesh="col_mrr1_hipr" />

                    <body
                        name="Lrr2_hipp"
                        pos="-4.650000000e-02 3.990000000e-02 0.000000000e+00"
                        euler="-0.000000000e+00 0.000000000e+00 -0.000000000e+00"
                    >
                        <joint
                            name="Jrr2_hipp"
                            type="hinge"
                            axis="0.0 -1.0 0.0"
                            range="-1.100000000e+02 1.100000000e+02"
                            armature="0.006180843"
                            damping="0.007"
                            frictionloss="0.194"
                        />
                        <inertial
                            pos="-2.005200000e-02 -8.413660000e-02 2.646100000e-03"
                            mass="1.510350900e+00"
                            fullinertia="3.928400000e-03 4.881300000e-03 7.857700000e-03 -1.879900000e-03 3.634000000e-04 2.345000000e-04"
                        />
                        <geom class="vis" mesh="vis_mrr2_hipp" />
                        <geom class="col" mesh="col_mrr2_hipp" />

                        <body
                            name="Lrr3_knee"
                            pos="-2.000000000e-01 -1.458000000e-01 0.000000000e+00"
                            euler="-0.000000000e+00 0.000000000e+00 -0.000000000e+00"
                        >
                            <joint
                                name="Jrr3_knee"
                                type="hinge"
                                axis="0.0 -1.0 0.0"
                                range="-1.000000000e+02 0.000000000e+00"
                                armature="0.006180843"
                                damping="0.007"
                                frictionloss="0.194"
                            />
                            <inertial
                                pos="1.119741000e-01 0.000000000e+00 -3.990870000e-02"
                                mass="3.694785000e-01"
                                fullinertia="5.015000000e-04 2.553300000e-03 2.082600000e-03 0.000000000e+00 8.986000000e-04 0.000000000e+00"
                            />
                            <geom class="vis" mesh="vis_mrr3_knee" />
                            <geom class="col" mesh="col_mrr3_knee" />

                            <body
                                name="Lrr4_foot"
                                pos="1.942564000e-01 0.000000000e+00 -8.890640000e-02"
                                euler="0.000000000e+00 -3.799999910e+01 0.000000000e+00"
                            >
                                <inertial
                                    pos="5.000000000e-07 -8.500000000e-06 -8.971600000e-03"
                                    mass="8.600240000e-02"
                                    fullinertia="2.820000000e-05 2.870000000e-05 3.350000000e-05 0.000000000e+00 0.000000000e+00 0.000000000e+00"
                                />
                                <geom class="vis_rubber" mesh="vis_mrr4_foot" />
                                <geom class="col_rubber" mesh="col_mrr4_foot" />
                            </body>
                        </body>
                    </body>
                </body>

            </body>
        </body>
    </worldbody>

    <contact>
        <!-- front left leg -->
        <exclude body1="L0_torso"   body2="Lfl1_hipr" />
        <exclude body1="L0_torso"   body2="Lfl2_hipp" />
        <exclude body1="Lfl1_hipr"  body2="Lfl2_hipp" />
        <exclude body1="Lfl2_hipp"  body2="Lfl3_knee" />
        <!-- front right leg -->
        <exclude body1="L0_torso"   body2="Lfr1_hipr" />
        <exclude body1="L0_torso"   body2="Lfr2_hipp" />
        <exclude body1="Lfr1_hipr"  body2="Lfr2_hipp" />
        <exclude body1="Lfr2_hipp"  body2="Lfr3_knee" />
        <!-- rear left leg -->
        <exclude body1="L0_torso"   body2="Lrl1_hipr" />
        <exclude body1="L0_torso"   body2="Lrl2_hipp" />
        <exclude body1="Lrl1_hipr"  body2="Lrl2_hipp" />
        <exclude body1="Lrl2_hipp"  body2="Lrl3_knee" />
        <!-- rear right leg -->
        <exclude body1="L0_torso"   body2="Lrr1_hipr" />
        <exclude body1="L0_torso"   body2="Lrr2_hipp" />
        <exclude body1="Lrr1_hipr"  body2="Lrr2_hipp" />
        <exclude body1="Lrr2_hipp"  body2="Lrr3_knee" />
    </contact>

    <actuator>
        <!-- front left leg -->
        <motor
            name="Rfl1_hipr" joint="Jfl1_hipr" gear="1"
            ctrlrange="-4.800000000e+01 4.800000000e+01"
            forcerange="-4.800000000e+01 4.800000000e+01"
        />
        <motor
            name="Rfl2_hipp" joint="Jfl2_hipp" gear="1"
            ctrlrange="-4.800000000e+01 4.800000000e+01"
            forcerange="-4.800000000e+01 4.800000000e+01"
        />
        <motor
            name="Rfl3_knee" joint="Jfl3_knee" gear="1"
            ctrlrange="-4.800000000e+01 4.800000000e+01"
            forcerange="-4.800000000e+01 4.800000000e+01"
        />
        <!-- front right leg -->
        <motor
            name="Rfr1_hipr" joint="Jfr1_hipr" gear="1"
            ctrlrange="-4.800000000e+01 4.800000000e+01"
            forcerange="-4.800000000e+01 4.800000000e+01"
        />
        <motor
            name="Rfr2_hipp" joint="Jfr2_hipp" gear="1"
            ctrlrange="-4.800000000e+01 4.800000000e+01"
            forcerange="-4.800000000e+01 4.800000000e+01"
        />
        <motor
            name="Rfr3_knee" joint="Jfr3_knee" gear="1"
            ctrlrange="-4.800000000e+01 4.800000000e+01"
            forcerange="-4.800000000e+01 4.800000000e+01"
        />
        <!-- rear left leg -->
        <motor
            name="Rrl1_hipr" joint="Jrl1_hipr" gear="1"
            ctrlrange="-4.800000000e+01 4.800000000e+01"
            forcerange="-4.800000000e+01 4.800000000e+01"
        />
        <motor
            name="Rrl2_hipp" joint="Jrl2_hipp" gear="1"
            ctrlrange="-4.800000000e+01 4.800000000e+01"
            forcerange="-4.800000000e+01 4.800000000e+01"
        />
        <motor
            name="Rrl3_knee" joint="Jrl3_knee" gear="1"
            ctrlrange="-4.800000000e+01 4.800000000e+01"
            forcerange="-4.800000000e+01 4.800000000e+01"
        />
        <!-- rear right leg -->
        <motor
            name="Rrr1_hipr" joint="Jrr1_hipr" gear="1"
            ctrlrange="-4.800000000e+01 4.800000000e+01"
            forcerange="-4.800000000e+01 4.800000000e+01"
        />
        <motor
            name="Rrr2_hipp" joint="Jrr2_hipp" gear="1"
            ctrlrange="-4.800000000e+01 4.800000000e+01"
            forcerange="-4.800000000e+01 4.800000000e+01"
        />
        <motor
            name="Rrr3_knee" joint="Jrr3_knee" gear="1"
            ctrlrange="-4.800000000e+01 4.800000000e+01"
            forcerange="-4.800000000e+01 4.800000000e+01"
        />
    </actuator>

    <sensor>
        <!-- joint position `q_J` -->

        <!--- front left leg -->
        <jointpos name="q_Jfl1_hipr" joint="Jfl1_hipr" noise='0.000' />
        <jointpos name="q_Jfl2_hipp" joint="Jfl2_hipp" noise='0.000' />
        <jointpos name="q_Jfl3_knee" joint="Jfl3_knee" noise='0.000' />
        <!--- front right leg -->
        <jointpos name="q_Jfr1_hipr" joint="Jfr1_hipr" noise='0.000' />
        <jointpos name="q_Jfr2_hipp" joint="Jfr2_hipp" noise='0.000' />
        <jointpos name="q_Jfr3_knee" joint="Jfr3_knee" noise='0.000' />
        <!--- rear left leg -->
        <jointpos name="q_Jrl1_hipr" joint="Jrl1_hipr" noise='0.000' />
        <jointpos name="q_Jrl2_hipp" joint="Jrl2_hipp" noise='0.000' />
        <jointpos name="q_Jrl3_knee" joint="Jrl3_knee" noise='0.000' />
        <!--- rear right leg -->
        <jointpos name="q_Jrr1_hipr" joint="Jrr1_hipr" noise='0.000' />
        <jointpos name="q_Jrr2_hipp" joint="Jrr2_hipp" noise='0.000' />
        <jointpos name="q_Jrr3_knee" joint="Jrr3_knee" noise='0.000' />

        <!-- joint velocity `dq_J` -->

        <!--- front left leg -->
        <jointvel name="dq_Jfl1_hipr" joint="Jfl1_hipr" noise='0.000' />
        <jointvel name="dq_Jfl2_hipp" joint="Jfl2_hipp" noise='0.000' />
        <jointvel name="dq_Jfl3_knee" joint="Jfl3_knee" noise='0.000' />
        <!--- front right leg -->
        <jointvel name="dq_Jfr1_hipr" joint="Jfr1_hipr" noise='0.000' />
        <jointvel name="dq_Jfr2_hipp" joint="Jfr2_hipp" noise='0.000' />
        <jointvel name="dq_Jfr3_knee" joint="Jfr3_knee" noise='0.000' />
        <!--- rear left leg -->
        <jointvel name="dq_Jrl1_hipr" joint="Jrl1_hipr" noise='0.000' />
        <jointvel name="dq_Jrl2_hipp" joint="Jrl2_hipp" noise='0.000' />
        <jointvel name="dq_Jrl3_knee" joint="Jrl3_knee" noise='0.000' />
        <!--- rear right leg -->
        <jointvel name="dq_Jrr1_hipr" joint="Jrr1_hipr" noise='0.000' />
        <jointvel name="dq_Jrr2_hipp" joint="Jrr2_hipp" noise='0.000' />
        <jointvel name="dq_Jrr3_knee" joint="Jrr3_knee" noise='0.000' />

        <!-- joint torque `tau_J` -->

        <!--- front left leg -->
        <jointactuatorfrc name="tau_Jfl1_hipr" joint="Jfl1_hipr" noise='0.000' />
        <jointactuatorfrc name="tau_Jfl2_hipp" joint="Jfl2_hipp" noise='0.000' />
        <jointactuatorfrc name="tau_Jfl3_knee" joint="Jfl3_knee" noise='0.000' />
        <!--- front right leg -->
        <jointactuatorfrc name="tau_Jfr1_hipr" joint="Jfr1_hipr" noise='0.000' />
        <jointactuatorfrc name="tau_Jfr2_hipp" joint="Jfr2_hipp" noise='0.000' />
        <jointactuatorfrc name="tau_Jfr3_knee" joint="Jfr3_knee" noise='0.000' />
        <!--- rear left leg -->
        <jointactuatorfrc name="tau_Jrl1_hipr" joint="Jrl1_hipr" noise='0.000' />
        <jointactuatorfrc name="tau_Jrl2_hipp" joint="Jrl2_hipp" noise='0.000' />
        <jointactuatorfrc name="tau_Jrl3_knee" joint="Jrl3_knee" noise='0.000' />
        <!--- rear right leg -->
        <jointactuatorfrc name="tau_Jrr1_hipr" joint="Jrr1_hipr" noise='0.000' />
        <jointactuatorfrc name="tau_Jrr2_hipp" joint="Jrr2_hipp" noise='0.000' />
        <jointactuatorfrc name="tau_Jrr3_knee" joint="Jrr3_knee" noise='0.000' />

        <!-- IMU -->
        <gyro           name="imu_gyro" site="imu" noise="0.000" />
        <accelerometer  name="imu_accl" site="imu" noise="0.000" />
        <framequat      name="imu_quat" objtype="site" objname="imu" noise="0.000" />
        <framepos       name="gt_pos"   objtype="site" objname="imu" />
        <framelinvel    name="gt_vel"   objtype="site" objname="imu" />
    </sensor>
</mujoco>
